{
  "created_at": "2021-10-06T17:00:36.047Z",
  "title": "Python 3.11: “Zero cost” exception handling",
  "url": "https://bugs.python.org/issue40222",
  "author": "rbanffy",
  "points": 196,
  "num_comments": 58,
  "_tags": [
    "story",
    "author_rbanffy",
    "story_28771931",
    "front_page"
  ],
  "objectID": "28771931",
  "original_created_at": "2021-10-06T11:48:05.000Z",
  "image": "https://bugs.python.org/@@file/committer.png",
  "localize": [
    {
      "locale": "ja",
      "title": "Python 3.11: \"ゼロコスト \"の例外処理"
    },
    {
      "locale": "zh",
      "title": "Python 3.11：\"零成本 \"异常处理"
    },
    {
      "locale": "zh-Hant",
      "title": "Python 3.11：\"零成本 \"異常處理"
    }
  ],
  "source_updated_at": 1633686001373
}